Workbook
Name Slicer_Locality: #N/A
Name Slicer_num_rooms: #N/A
Name Slicer_Residential: #N/A
Name Slicer_Year: #N/A

Sheet V3
A1: Date | B1: Year | C1: Locality | D1: Estimated Value | E1: Sale Price | F1: Property | G1: Residential | H1: num_rooms | I1: num_bathrooms | J1: carpet_area | K1: property_tax_rate | L1: Face
A2: 39815 | B2: 2009 | C2: Waterbury | D2: 111440 | E2: 185000 | F2: Single Family | G2: Detached House | H2: 3 | I2: 3 | J2: 996 | K2: 1.025953 | L2: South
A3: 39815 | B3: 2009 | C3: Waterbury | D3: 50540 | E3: 105000 | F3: Single Family | G3: Detached House | H3: 3 | I3: 1 | J3: 951 | K3: 1.025953 | L3: East
A4: 39815 | B4: 2009 | C4: Bridgeport | D4: 4775276 | E4: 272900 | F4: Single Family | G4: Detached House | H4: 3 | I4: 1 | J4: 971 | K4: 1.025953 | L4: East
A5: 39817 | B5: 2009 | C5: Norwalk | D5: 208880 | E5: 370000 | F5: Single Family | G5: Detached House | H5: 3 | I5: 2 | J5: 1063 | K5: 1.025953 | L5: South
A6: 39817 | B6: 2009 | C6: Waterbury | D6: 83300 | E6: 220000 | F6: Two Family | G6: Duplex | H6: 4 | I6: 4 | J6: 1471 | K6: 1.025953 | L6: South
A7: 39818 | B7: 2009 | C7: Greenwich | D7: 2095100 | E7: 2860000 | F7: Single Family | G7: Detached House | H7: 3 | I7: 1 | J7: 963 | K7: 1.025953 | L7: East
A8: 39818 | B8: 2009 | C8: Norwalk | D8: 186410 | E8: 340000 | F8: Single Family | G8: Detached House | H8: 3 | I8: 2 | J8: 933 | K8: 1.025953 | L8: East
A9: 39821 | B9: 2009 | C9: Waterbury | D9: 56070 | E9: 75000 | F9: Two Family | G9: Duplex | H9: 4 | I9: 2 | J9: 1373 | K9: 1.025953 | L9: West
A10: 39821 | B10: 2009 | C10: Bridgeport | D10: 160904 | E10: 399900 | F10: Two Family | G10: Duplex | H10: 4 | I10: 2 | J10: 1284 | K10: 1.025953 | L10: East
A11: 39821 | B11: 2009 | C11: Norwalk | D11: 342090 | E11: 850000 | F11: Single Family | G11: Detached House | H11: 3 | I11: 1 | J11: 914 | K11: 1.025953 | L11: East
A12: 39821 | B12: 2009 | C12: Bridgeport | D12: 71050 | E12: 280000 | F12: Two Family | G12: Duplex | H12: 4 | I12: 3 | J12: 1295 | K12: 1.025953 | L12: East
A13: 39822 | B13: 2009 | C13: Bridgeport | D13: 135870 | E13: 362560 | F13: Two Family | G13: Duplex | H13: 4 | I13: 2 | J13: 1338 | K13: 1.025953 | L13: West
... A5493: 44834 | B5493: 2022 | C5493: West Hartford | D5493: 124740 | E5493: 225635 | F5493: Single Family | G5493: Detached House | H5493: 3 | I5493: 1 | J5493: 922 | K5493: 1.003979 | L5493: North

Sheet celan data 
A1: Date | B1: Year | C1: Locality | D1: Estimated Value | E1: Sale Price | F1: Property | G1: Residential | H1: num_rooms | I1: num_bathrooms | J1: carpet_area | K1: property_tax_rate | L1: Face
A2: 39815 | B2: 2009 | C2: Waterbury | D2: 111440 | E2: 185000 | F2: Single Family | G2: Detached House | H2: 3 | I2: 3 | J2: 996 | K2: 1.025953 | L2: South
A3: 39816 | B3: 2009 | C3: Waterbury | D3: 50540 | E3: 105000 | F3: Single Family | G3: Detached House | H3: 3 | I3: 1 | J3: 951 | K3: 1.025953 | L3: East
A4: 39817 | B4: 2009 | C4: Bridgeport | D4: 4775276 | E4: 272900 | F4: Single Family | G4: Detached House | H4: 3 | I4: 1 | J4: 971 | K4: 1.025953 | L4: East
A5: 39818 | B5: 2009 | C5: Norwalk | D5: 208880 | E5: 370000 | F5: Single Family | G5: Detached House | H5: 3 | I5: 2 | J5: 1063 | K5: 1.025953 | L5: South
A6: 39819 | B6: 2009 | C6: Waterbury | D6: 83300 | E6: 220000 | F6: Two Family | G6: Duplex | H6: 4 | I6: 4 | J6: 1471 | K6: 1.025953 | L6: South
A7: 39820 | B7: 2009 | C7: Greenwich | D7: 2095100 | E7: 2860000 | F7: Single Family | G7: Detached House | H7: 3 | I7: 1 | J7: 963 | K7: 1.025953 | L7: East
A8: 39821 | B8: 2009 | C8: Norwalk | D8: 186410 | E8: 340000 | F8: Single Family | G8: Detached House | H8: 3 | I8: 2 | J8: 933 | K8: 1.025953 | L8: East
A9: 39822 | B9: 2009 | C9: Waterbury | D9: 56070 | E9: 75000 | F9: Two Family | G9: Duplex | H9: 4 | I9: 2 | J9: 1373 | K9: 1.025953 | L9: West
A10: 39823 | B10: 2009 | C10: Bridgeport | D10: 160904 | E10: 399900 | F10: Two Family | G10: Duplex | H10: 4 | I10: 2 | J10: 1284 | K10: 1.025953 | L10: East
A11: 39824 | B11: 2009 | C11: Norwalk | D11: 342090 | E11: 850000 | F11: Single Family | G11: Detached House | H11: 3 | I11: 1 | J11: 914 | K11: 1.025953 | L11: East
A12: 39825 | B12: 2009 | C12: Bridgeport | D12: 71050 | E12: 280000 | F12: Two Family | G12: Duplex | H12: 4 | I12: 3 | J12: 1295 | K12: 1.025953 | L12: East
A13: 39826 | B13: 2009 | C13: Bridgeport | D13: 135870 | E13: 362560 | F13: Two Family | G13: Duplex | H13: 4 | I13: 2 | J13: 1338 | K13: 1.025953 | L13: West
... A5493: 44834 | B5493: 2022 | C5493: West Hartford | D5493: 124740 | E5493: 225635 | F5493: Single Family | G5493: Detached House | H5493: 3 | I5493: 1 | J5493: 922 | K5493: 1.003979 | L5493: North

Sheet pivot ana
A3: Row Labels | B3: Average of Sale Price
A4: Bridgeport | B4: 177767.7
A5: Fairfield | B5: 738969.45
A6: Greenwich | B6: 2229739.7
A7: Norwalk | B7: 569822.76
A8: Stamford | B8: 647855.46
A9: Waterbury | B9: 108362.87
A10: West Hartford | B10: 333589.59
A11: Grand Total | B11: 625444.55
B19: Row Labels | C19: Sum of Sale Price
B20: Bridgeport | C20: 189322600
B21: Fairfield | C21: 628124033
B22: Greenwich | C22: 1509533785
B23: Norwalk | C23: 361837452
B24: Stamford | C24: 414627492
B25: Waterbury | C25: 101319281
B26: West Hartford | C26: 230176818
B27: Grand Total | C27: 3434941461
D36: Row Labels | E36: Average of Sale Price
D37: Detached House | E37: 705426.37
D38: Duplex | E38: 270238.45
D39: Fourplex | E39: 215878.67
D40: Triplex | E40: 181581.58
D41: Grand Total | E41: 625444.55
D48: Row Labels | E48: Average of Sale Price
D49: 3 | E49: 705426.37
D50: 4 | E50: 270238.45
D51: 6 | E51: 181581.58
D52: 8 | E52: 215878.67
D53: Grand Total | E53: 625444.55
E60: Row Labels | F60: Average of price per. Sq. ft
E61: Bridgeport | F61: 151.34315
E62: Fairfield | F62: 740.78473
E63: Greenwich | F63: 2213.8074
E64: Norwalk | F64: 558.45667
E65: Stamford | F65: 629.12242
E66: Waterbury | F66: 97.074145
E67: West Hartford | F67: 329.11942
E68: Grand Total | F68: 612.65662
C75: Row Labels | D75: Count of Date
...

Sheet calculated data 
A1: Date | B1: Year | C1: Locality | D1: Estimated Value | E1: Sale Price | F1: Property | G1: Residential | H1: num_rooms | I1: num_bathrooms | J1: carpet_area | K1: property_tax_rate | L1: Face | M1: price per. Sq. ft | N1: price diffrence | O1: pd % | P1: sale status
A2: 39815 | B2: 2009 | C2: Waterbury | D2: 111440 | E2: 185000 | F2: Single Family | G2: Detached House | H2: 3 | I2: 3 | J2: 996 | K2: 1.025953 | L2: South | M2: =V3__67[[#This Row],[Sale Price]]/V3__67[[#This Row],[carpet_area]] -> 185.74297 | N2: =IF(OR(V3__67[[#This Row],[Estimated Value]]="",V3__67[[#This Row],[Estimated Value]]=0),"",V3__67[[#This Row],[Sale Price]]-V3__67[[#This Row],[Estimated Value]]) -> 73560 | O2: =IF(OR(V3__67[[#This Row],[Estimated Value]]="",V3__67[[#This Row],[Estimated Value]]=0),"",(V3__67[[#This Row],[Sale Price]]-V3__67[[#This Row],[Estimated Value]])/V3__67[[#This Row],[Estimated Value]]) -> 0.66008615 | P2: =IF(N2="","No Estimate",IF(N2>0,"Above Estimate",IF(N2<0,"Below Estimate","At Estimate"))) -> Above Estimate
A3: 39816 | B3: 2009 | C3: Waterbury | D3: 50540 | E3: 105000 | F3: Single Family | G3: Detached House | H3: 3 | I3: 1 | J3: 951 | K3: 1.025953 | L3: East | M3: =V3__67[[#This Row],[Sale Price]]/V3__67[[#This Row],[carpet_area]] -> 110.41009 | N3: =IF(OR(V3__67[[#This Row],[Estimated Value]]="",V3__67[[#This Row],[Estimated Value]]=0),"",V3__67[[#This Row],[Sale Price]]-V3__67[[#This Row],[Estimated Value]]) -> 54460 | O3: =IF(OR(V3__67[[#This Row],[Estimated Value]]="",V3__67[[#This Row],[Estimated Value]]=0),"",(V3__67[[#This Row],[Sale Price]]-V3__67[[#This Row],[Estimated Value]])/V3__67[[#This Row],[Estimated Value]]) -> 1.0775623 | P3: =IF(N3="","No Estimate",IF(N3>0,"Above Estimate",IF(N3<0,"Below Estimate","At Estimate"))) -> Above Estimate
A4: 39817 | B4: 2009 | C4: Bridgeport | D4: 4775276 | E4: 272900 | F4: Single Family | G4: Detached House | H4: 3 | I4: 1 | J4: 971 | K4: 1.025953 | L4: East | M4: =V3__67[[#This Row],[Sale Price]]/V3__67[[#This Row],[carpet_area]] -> 281.05046 | N4: =IF(OR(V3__67[[#This Row],[Estimated Value]]="",V3__67[[#This Row],[Estimated Value]]=0),"",V3__67[[#This Row],[Sale Price]]-V3__67[[#This Row],[Estimated Value]]) -> -4502376 | O4: =IF(OR(V3__67[[#This Row],[Estimated Value]]="",V3__67[[#This Row],[Estimated Value]]=0),"",(V3__67[[#This Row],[Sale Price]]-V3__67[[#This Row],[Estimated Value]])/V3__67[[#This Row],[Estimated Value]]) -> -0.94285147 | P4: =IF(N4="","No Estimate",IF(N4>0,"Above Estimate",IF(N4<0,"Below Estimate","At Estimate"))) -> Below Estimate
A5: 39818 | B5: 2009 | C5: Norwalk | D5: 208880 | E5: 370000 | F5: Single Family | G5: Detached House | H5: 3 | I5: 2 | J5: 1063 | K5: 1.025953 | L5: South | M5: =V3__67[[#This Row],[Sale Price]]/V3__67[[#This Row],[carpet_area]] -> 348.0715 | N5: =IF(OR(V3__67[[#This Row],[Estimated Value]]="",V3__67[[#This Row],[Estimated Value]]=0),"",V3__67[[#This Row],[Sale Price]]-V3__67[[#This Row],[Estimated Value]]) -> 161120 | O5: =IF(OR(V3__67[[#This Row],[Estimated Value]]="",V3__67[[#This Row],[Estimated Value]]=0),"",(V3__67[[#This Row],[Sale Price]]-V3__67[[#This Row],[Estimated Value]])/V3__67[[#This Row],[Estimated Value]]) -> 0.77135197 | P5: =IF(N5="","No Estimate",IF(N5>0,"Above Estimate",IF(N5<0,"Below Estimate","At Estimate"))) -> Above Estimate
A6: 39819 | B6: 2009 | C6: Waterbury | D6: 83300 | E6: 220000 | F6: Two Family | G6: Duplex | H6: 4 | I6: 4 | J6: 1471 | K6: 1.025953 | L6: South | M6: =V3__67[[#This Row],[Sale Price]]/V3__67[[#This Row],[carpet_area]] -> 149.55812 | N6: =IF(OR(V3__67[[#This Row],[Estimated Value]]="",V3__67[[#This Row],[Estimated Value]]=0),"",V3__67[[#This Row],[Sale Price]]-V3__67[[#This Row],[Estimated Value]]) -> 136700 | O6: =IF(OR(V3__67[[#This Row],[Estimated Value]]="",V3__67[[#This Row],[Estimated Value]]=0),"",(V3__67[[#This Row],[Sale Price]]-V3__67[[#This Row],[Estimated Value]])/V3__67[[#This Row],[Estimated Value]]) -> 1.6410564 | P6: =IF(N6="","No Estimate",IF(N6>0,"Above Estimate",IF(N6<0,"Below Estimate","At Estimate"))) -> Above Estimate
A7: 39820 | B7: 2009 | C7: Greenwich | D7: 2095100 | E7: 2860000 | F7: Single Family | G7: Detached House | H7: 3 | I7: 1 | J7: 963 | K7: 1.025953 | L7: East | M7: =V3__67[[#This Row],[Sale Price]]/V3__67[[#This Row],[carpet_area]] -> 2969.8858 | N7: =IF(OR(V3__67[[#This Row],[Estimated Value]]="",V3__67[[#This Row],[Estimated Value]]=0),"",V3__67[[#This Row],[Sale Price]]-V3__67[[#This Row],[Estimated Value]]) -> 764900 | O7: =IF(OR(V3__67[[#This Row],[Estimated Value]]="",V3__67[[#This Row],[Estimated Value]]=0),"",(V3__67[[#This Row],[Sale Price]]-V3__67[[#This Row],[Estimated Value]])/V3__67[[#This Row],[Estimated Value]]) -> 0.36508997 | P7: =IF(N7="","No Estimate",IF(N7>0,"Above Estimate",IF(N7<0,"Below Estimate","At Estimate"))) -> Above Estimate
A8: 39821 | B8: 2009 | C8: Norwalk | D8: 186410 | E8: 340000 | F8: Single Family | G8: Detached House | H8: 3 | I8: 2 | J8: 933 | K8: 1.025953 | L8: East | M8: =V3__67[[#This Row],[Sale Price]]/V3__67[[#This Row],[carpet_area]] -> 364.41586 | N8: =IF(OR(V3__67[[#This Row],[Estimated Value]]="",V3__67[[#This Row],[Estimated Value]]=0),"",V3__67[[#This Row],[Sale Price]]-V3__67[[#This Row],[Estimated Value]]) -> 153590 | O8: =IF(OR(V3__67[[#This Row],[Estimated Value]]="",V3__67[[#This Row],[Estimated Value]]=0),"",(V3__67[[#This Row],[Sale Price]]-V3__67[[#This Row],[Estimated Value]])/V3__67[[#This Row],[Estimated Value]]) -> 0.82393648 | P8: =IF(N8="","No Estimate",IF(N8>0,"Above Estimate",IF(N8<0,"Below Estimate","At Estimate"))) -> Above Estimate
A9: 39822 | B9: 2009 | C9: Waterbury | D9: 56070 | E9: 75000 | F9: Two Family | G9: Duplex | H9: 4 | I9: 2 | J9: 1373 | K9: 1.025953 | L9: West | M9: =V3__67[[#This Row],[Sale Price]]/V3__67[[#This Row],[carpet_area]] -> 54.624909 | N9: =IF(OR(V3__67[[#This Row],[Estimated Value]]="",V3__67[[#This Row],[Estimated Value]]=0),"",V3__67[[#This Row],[Sale Price]]-V3__67[[#This Row],[Estimated Value]]) -> 18930 | O9: =IF(OR(V3__67[[#This Row],[Estimated Value]]="",V3__67[[#This Row],[Estimated Value]]=0),"",(V3__67[[#This Row],[Sale Price]]-V3__67[[#This Row],[Estimated Value]])/V3__67[[#This Row],[Estimated Value]]) -> 0.3376137 | P9: =IF(N9="","No Estimate",IF(N9>0,"Above Estimate",IF(N9<0,"Below Estimate","At Estimate"))) -> Above Estimate
A10: 39823 | B10: 2009 | C10: Bridgeport | D10: 160904 | E10: 399900 | F10: Two Family | G10: Duplex | H10: 4 | I10: 2 | J10: 1284 | K10: 1.025953 | L10: East | M10: =V3__67[[#This Row],[Sale Price]]/V3__67[[#This Row],[carpet_area]] -> 311.4486 | N10: =IF(OR(V3__67[[#This Row],[Estimated Value]]="",V3__67[[#This Row],[Estimated Value]]=0),"",V3__67[[#This Row],[Sale Price]]-V3__67[[#This Row],[Estimated Value]]) -> 238996 | O10: =IF(OR(V3__67[[#This Row],[Estimated Value]]="",V3__67[[#This Row],[Estimated Value]]=0),"",(V3__67[[#This Row],[Sale Price]]-V3__67[[#This Row],[Estimated Value]])/V3__67[[#This Row],[Estimated Value]]) -> 1.4853329 | P10: =IF(N10="","No Estimate",IF(N10>0,"Above Estimate",IF(N10<0,"Below Estimate","At Estimate"))) -> Above Estimate
A11: 39824 | B11: 2009 | C11: Norwalk | D11: 342090 | E11: 850000 | F11: Single Family | G11: Detached House | H11: 3 | I11: 1 | J11: 914 | K11: 1.025953 | L11: East | M11: =V3__67[[#This Row],[Sale Price]]/V3__67[[#This Row],[carpet_area]] -> 929.97812 | N11: =IF(OR(V3__67[[#This Row],[Estimated Value]]="",V3__67[[#This Row],[Estimated Value]]=0),"",V3__67[[#This Row],[Sale Price]]-V3__67[[#This Row],[Estimated Value]]) -> 507910 | O11: =IF(OR(V3__67[[#This Row],[Estimated Value]]="",V3__67[[#This Row],[Estimated Value]]=0),"",(V3__67[[#This Row],[Sale Price]]-V3__67[[#This Row],[Estimated Value]])/V3__67[[#This Row],[Estimated Value]]) -> 1.4847262 | P11: =IF(N11="","No Estimate",IF(N11>0,"Above Estimate",IF(N11<0,"Below Estimate","At Estimate"))) -> Above Estimate
A12: 39825 | B12: 2009 | C12: Bridgeport | D12: 71050 | E12: 280000 | F12: Two Family | G12: Duplex | H12: 4 | I12: 3 | J12: 1295 | K12: 1.025953 | L12: East | M12: =V3__67[[#This Row],[Sale Price]]/V3__67[[#This Row],[carpet_area]] -> 216.21622 | N12: =IF(OR(V3__67[[#This Row],[Estimated Value]]="",V3__67[[#This Row],[Estimated Value]]=0),"",V3__67[[#This Row],[Sale Price]]-V3__67[[#This Row],[Estimated Value]]) -> 208950 | O12: =IF(OR(V3__67[[#This Row],[Estimated Value]]="",V3__67[[#This Row],[Estimated Value]]=0),"",(V3__67[[#This Row],[Sale Price]]-V3__67[[#This Row],[Estimated Value]])/V3__67[[#This Row],[Estimated Value]]) -> 2.9408867 | P12: =IF(N12="","No Estimate",IF(N12>0,"Above Estimate",IF(N12<0,"Below Estimate","At Estimate"))) -> Above Estimate
A13: 39826 | B13: 2009 | C13: Bridgeport | D13: 135870 | E13: 362560 | F13: Two Family | G13: Duplex | H13: 4 | I13: 2 | J13: 1338 | K13: 1.025953 | L13: West | M13: =V3__67[[#This Row],[Sale Price]]/V3__67[[#This Row],[carpet_area]] -> 270.9716 | N13: =IF(OR(V3__67[[#This Row],[Estimated Value]]="",V3__67[[#This Row],[Estimated Value]]=0),"",V3__67[[#This Row],[Sale Price]]-V3__67[[#This Row],[Estimated Value]]) -> 226690 | O13: =IF(OR(V3__67[[#This Row],[Estimated Value]]="",V3__67[[#This Row],[Estimated Value]]=0),"",(V3__67[[#This Row],[Sale Price]]-V3__67[[#This Row],[Estimated Value]])/V3__67[[#This Row],[Estimated Value]]) -> 1.6684331 | P13: =IF(N13="","No Estimate",IF(N13>0,"Above Estimate",IF(N13<0,"Below Estimate","At Estimate"))) -> Above Estimate
... A5493: 44834 | B5493: 2022 | C5493: West Hartford | D5493: 124740 | E5493: 225635 | F5493: Single Family | G5493: Detached House | H5493: 3 | I5493: 1 | J5493: 922 | K5493: 1.003979 | L5493: North | M5493: =V3__67[[#This Row],[Sale Price]]/V3__67[[#This Row],[carpet_area]] -> 244.72343 | N5493: =IF(OR(V3__67[[#This Row],[Estimated Value]]="",V3__67[[#This Row],[Estimated Value]]=0),"",V3__67[[#This Row],[Sale Price]]-V3__67[[#This Row],[Estimated Value]]) -> 100895 | O5493: =IF(OR(V3__67[[#This Row],[Estimated Value]]="",V3__67[[#This Row],[Estimated Value]]=0),"",(V3__67[[#This Row],[Sale Price]]-V3__67[[#This Row],[Estimated Value]])/V3__67[[#This Row],[Estimated Value]]) -> 0.80884239 | P5493: =IF(N5493="","No Estimate",IF(N5493>0,"Above Estimate",IF(N5493<0,"Below Estimate","At Estimate"))) -> Above Estimate

Sheet data
A1: coulmn | B1: meaning | C1: data type | D1: example
A2: Date | B2: date of property transaction | C2: date | D2: 39815 | G2: =COUNTA('calculated data '!A:A)-1 -> 5492
A3: Year | B3: year of transaction | C3: integer | D3: 2009 | H3: avg sale | I3: =AVERAGE(V3__67[[#All],[Sale Price]]) -> 625444.55
A4: Locality | B4: location of property | C4: text | D4: waterbury | K4: min sale | L4: =MIN(V3__67[Sale Price]) -> 2500
A5: Estimated Value | B5: Estimated/assessed property value | C5: numeric | D5: 250000 | H5: median sale | I5: =MEDIAN(V3__67[Sale Price]) -> 336500
A6: sale perice | B6: Actual recorded sale price | C6: numeric | D6: 300000 | F6: total sale | G6: =SUM(V3__67[Sale Price]) -> 3434941461 | K6: max ssale | L6: =MAX(V3__67[Sale Price]) -> 18500000
A7: property | B7: Property classification | C7: text | D7: single family
A8: =V3_[[#Headers],[Residential]] -> Residential | B8: Residential property type | C8: text | D8: detached house
A9: =V3_[[#Headers],[num_rooms]] -> num_rooms | B9: Number of rooms | C9: integer | D9: 3
A10: =V3_[[#Headers],[num_bathrooms]] -> num_bathrooms | B10: Number of bathrooms | C10: =C9 -> integer | D10: 2 | G10: avg carpet area | H10: =AVERAGE(V3__67[carpet_area]) -> 1109.5559
A11: =V3_[[#Headers],[carpet_area]] -> carpet_area | B11: Carpet area | C11: =C5 -> numeric | D11: 996
A12: =V3_[[#Headers],[property_tax_rate]] -> property_tax_rate | B12: Property tax rate | C12: =C11 -> numeric | D12: 1.025953 | G12: avg price sq.ft | H12: =AVERAGE(V3__67[price per. Sq. ft]) -> 612.65662
A13: south | B13: south | C13: south | D13: south
A14: price per sq.ft. | B14: actual sale pricec / carpet area | C14: numeric | D14: 5000 | G14: avg rooms | H14: =AVERAGE(V3__67[num_rooms]) -> 3.3241078
A15: price diffrence | B15: diff between actual and estimeted price | C15: numeric | D15: 70500
A16: price diffrence % | B16: Percentage difference between actual and estimated value | C16: percentage | D16: 0.065
A17: sales status | B17: Indicates whether sale price was above, below, or equal to estimated value | C17: text | D17: above estimated
A27: Residential | B27: Transactions | C27: Average Price | D27: Total Sales
A28: Detached House | B28: =COUNTIFS(V3__67[Residential],A28) -> 4554 | C28: =AVERAGEIFS(V3__67[Sale Price],V3__67[Residential],'calculated data '!G5433) -> 705426.37 | D28: =SUMIFS(V3__67[Sale Price],V3__67[Residential],'calculated data '!G5431) -> 3212511687
A29: Duplex | B29: =COUNTIFS(V3__67[Residential],'calculated data '!G5411) -> 568 | C29: =AVERAGEIFS('calculated data '!E1:E5483,'calculated data '!G1:G5483,'calculated data '!G6) -> 270238.45 | D29: =SUMIFS('calculated data '!E:E,'calculated data '!G:G,'calculated data '!G6) -> 153495438
A30: Triplex | B30: =COUNTIFS(V3__67[Residential],'calculated data '!G5426) -> 319 | C30: =AVERAGEIFS('calculated data '!E:E,'calculated data '!G:G,'calculated data '!G15) -> 181581.58 | D30: =SUMIFS('calculated data '!E:E,'calculated data '!G:G,'calculated data '!G15) -> 57924524
A31: Fourplex | B31: 51 | C31: =AVERAGEIFS('calculated data '!E:E,'calculated data '!G:G,'calculated data '!G47) -> 215878.67 | D31: =SUMIFS('calculated data '!E:E,'calculated data '!G:G,'calculated data '!G47) -> 11009812
B39: locality analysis
A41: Locality | B41: Transactions | C41: Average Sale Price | D41: Average ₹/sq.ft. | E41: Total Sales
A42: Bridgeport | B42: =COUNTIFS(V3__67[Locality],'calculated data '!C4) -> 1065 | C42: =AVERAGEIFS(V3__67[Sale Price],V3__67[Locality],'calculated data '!C462) -> 177767.7 | D42: =AVERAGEIFS(V3__67[price per. Sq. ft],V3__67[Locality],data!A42) -> 151.34315 | E42: =SUMIFS(V3__67[Sale Price],V3__67[Locality],data!A42) -> 189322600
A43: Fairfield | B43: =COUNTIFS(V3__67[Locality],'calculated data '!C27) -> 850 | C43: =AVERAGEIFS(V3__67[Sale Price],V3__67[Locality],data!A43) -> 738969.45 | D43: =AVERAGEIFS(V3__67[price per. Sq. ft],V3__67[Locality],data!A43) -> 740.78473 | E43: =SUMIFS(V3__67[Sale Price],V3__67[Locality],data!A43) -> 628124033
A44: Greenwich | B44: =COUNTIFS(V3__67[Locality],'calculated data '!C7) -> 677 | C44: =AVERAGEIFS(V3__67[Sale Price],V3__67[Locality],data!A44) -> 2229739.7 | D44: =AVERAGEIFS(V3__67[price per. Sq. ft],V3__67[Locality],data!A44) -> 2213.8074 | E44: =SUMIFS(V3__67[Sale Price],V3__67[Locality],data!A44) -> 1509533785
A45: Norwalk | B45: =COUNTIFS(V3__67[Locality],'calculated data '!C28) -> 635 | C45: =AVERAGEIFS(V3__67[Sale Price],V3__67[Locality],data!A45) -> 569822.76 | D45: =AVERAGEIFS(V3__67[price per. Sq. ft],V3__67[Locality],data!A45) -> 558.45667 | E45: =SUMIFS(V3__67[Sale Price],V3__67[Locality],data!A45) -> 361837452
A46: Stamford | B46: =COUNTIFS(V3__67[Locality],data!A46) -> 640 | C46: =AVERAGEIFS(V3__67[Sale Price],V3__67[Locality],data!A46) -> 647855.46 | D46: =AVERAGEIFS(V3__67[price per. Sq. ft],V3__67[Locality],data!A46) -> 629.12242 | E46: =SUMIFS(V3__67[Sale Price],V3__67[Locality],data!A46) -> 414627492
A47: Waterbury | B47: =COUNTIFS(V3__67[Locality],data!A47) -> 935 | C47: =AVERAGEIFS(V3__67[Sale Price],V3__67[Locality],data!A47) -> 108362.87 | D47: =AVERAGEIFS(V3__67[price per. Sq. ft],V3__67[Locality],data!A47) -> 97.074145 | E47: =SUMIFS(V3__67[Sale Price],V3__67[Locality],data!A47) -> 101319281
A48: West Hartford | B48: =COUNTIFS(V3__67[Locality],'calculated data '!C468) -> 690 | C48: =AVERAGEIFS(V3__67[Sale Price],V3__67[Locality],data!A48) -> 333589.59 | D48: =AVERAGEIFS(V3__67[price per. Sq. ft],V3__67[Locality],data!A48) -> 329.11942 | E48: =SUMIFS(V3__67[Sale Price],V3__67[Locality],data!A48) -> 230176818

Sheet Sheet10
B1: REAL ESTATE MARKET & INVESTMENT INTELLIGENCE
B4: =data!G2 -> 5492 | D4: =data!G6 -> 3434941461 | F4: =data!I3 -> 625444.55 | H4: =data!I5 -> 336500 | J4: =data!H12 -> 612.65662
B5: TOTAL TRANSACTION | D5: TOTAL SALE | F5: AVG.SALE PRICE | H5: MEDIAN PRICE | J5: Average ₹/sq.ft.
